<?xml version="1.0" ?>
<!-- =================================================================================== -->
<!-- |    This document was autogenerated by xacro from jamie.xacro                    | -->
<!-- |    EDITING THIS FILE BY HAND IS NOT RECOMMENDED                                 | -->
<!-- =================================================================================== -->
<robot name="jamie">
  <material name="silver_default">
    <color rgba="0.700 0.700 0.700 1.000"/>
  </material>
  <material name="steel_satin">
    <color rgba="0.6274509803921569 0.6274509803921569 0.6274509803921569 1.0"/>
  </material>
  <material name="aluminum_anodized_glossy_red">
    <color rgba="0.043137254901960784 0.4196078431372549 0.8784313725490196 1.0"/>
  </material>
  <material name="led_green">
    <color rgba="0.26666666666666666 0.5882352941176471 0.2823529411764706 0.0"/>
  </material>
  <transmission name="RightHip_tran">
    <type>transmission_interface/SimpleTransmission</type>
    <joint name="RightHip">
      <hardwareInterface>hardware_interface/EffortJointInterface</hardwareInterface>
    </joint>
    <actuator name="RightHip_actr">
      <hardwareInterface>hardware_interface/EffortJointInterface</hardwareInterface>
      <mechanicalReduction>1</mechanicalReduction>
    </actuator>
  </transmission>
  <transmission name="TorsoBow_tran">
    <type>transmission_interface/SimpleTransmission</type>
    <joint name="TorsoBow">
      <hardwareInterface>hardware_interface/EffortJointInterface</hardwareInterface>
    </joint>
    <actuator name="TorsoBow_actr">
      <hardwareInterface>hardware_interface/EffortJointInterface</hardwareInterface>
      <mechanicalReduction>1</mechanicalReduction>
    </actuator>
  </transmission>
  <transmission name="TorsoTilt_tran">
    <type>transmission_interface/SimpleTransmission</type>
    <joint name="TorsoTilt">
      <hardwareInterface>hardware_interface/EffortJointInterface</hardwareInterface>
    </joint>
    <actuator name="TorsoTilt_actr">
      <hardwareInterface>hardware_interface/EffortJointInterface</hardwareInterface>
      <mechanicalReduction>1</mechanicalReduction>
    </actuator>
  </transmission>
  <transmission name="RightChest_tran">
    <type>transmission_interface/SimpleTransmission</type>
    <joint name="RightChest">
      <hardwareInterface>hardware_interface/EffortJointInterface</hardwareInterface>
    </joint>
    <actuator name="RightChest_actr">
      <hardwareInterface>hardware_interface/EffortJointInterface</hardwareInterface>
      <mechanicalReduction>1</mechanicalReduction>
    </actuator>
  </transmission>
  <transmission name="HeadTurn_tran">
    <type>transmission_interface/SimpleTransmission</type>
    <joint name="HeadTurn">
      <hardwareInterface>hardware_interface/EffortJointInterface</hardwareInterface>
    </joint>
    <actuator name="HeadTurn_actr">
      <hardwareInterface>hardware_interface/EffortJointInterface</hardwareInterface>
      <mechanicalReduction>1</mechanicalReduction>
    </actuator>
  </transmission>
  <transmission name="HeadNod_tran">
    <type>transmission_interface/SimpleTransmission</type>
    <joint name="HeadNod">
      <hardwareInterface>hardware_interface/EffortJointInterface</hardwareInterface>
    </joint>
    <actuator name="HeadNod_actr">
      <hardwareInterface>hardware_interface/EffortJointInterface</hardwareInterface>
      <mechanicalReduction>1</mechanicalReduction>
    </actuator>
  </transmission>
  <transmission name="RightBicep_tran">
    <type>transmission_interface/SimpleTransmission</type>
    <joint name="RightBicep">
      <hardwareInterface>hardware_interface/EffortJointInterface</hardwareInterface>
    </joint>
    <actuator name="RightBicep_actr">
      <hardwareInterface>hardware_interface/EffortJointInterface</hardwareInterface>
      <mechanicalReduction>1</mechanicalReduction>
    </actuator>
  </transmission>
  <transmission name="RightElbow_tran">
    <type>transmission_interface/SimpleTransmission</type>
    <joint name="RightElbow">
      <hardwareInterface>hardware_interface/EffortJointInterface</hardwareInterface>
    </joint>
    <actuator name="RightElbow_actr">
      <hardwareInterface>hardware_interface/EffortJointInterface</hardwareInterface>
      <mechanicalReduction>1</mechanicalReduction>
    </actuator>
  </transmission>
  <transmission name="RightKnee_tran">
    <type>transmission_interface/SimpleTransmission</type>
    <joint name="RightKnee">
      <hardwareInterface>hardware_interface/EffortJointInterface</hardwareInterface>
    </joint>
    <actuator name="RightKnee_actr">
      <hardwareInterface>hardware_interface/EffortJointInterface</hardwareInterface>
      <mechanicalReduction>1</mechanicalReduction>
    </actuator>
  </transmission>
  <transmission name="RightAnkle_tran">
    <type>transmission_interface/SimpleTransmission</type>
    <joint name="RightAnkle">
      <hardwareInterface>hardware_interface/EffortJointInterface</hardwareInterface>
    </joint>
    <actuator name="RightAnkle_actr">
      <hardwareInterface>hardware_interface/EffortJointInterface</hardwareInterface>
      <mechanicalReduction>1</mechanicalReduction>
    </actuator>
  </transmission>
  <transmission name="HeadTilt_tran">
    <type>transmission_interface/SimpleTransmission</type>
    <joint name="HeadTilt">
      <hardwareInterface>hardware_interface/EffortJointInterface</hardwareInterface>
    </joint>
    <actuator name="HeadTilt_actr">
      <hardwareInterface>hardware_interface/EffortJointInterface</hardwareInterface>
      <mechanicalReduction>1</mechanicalReduction>
    </actuator>
  </transmission>
  <transmission name="LeftHip_tran">
    <type>transmission_interface/SimpleTransmission</type>
    <joint name="LeftHip">
      <hardwareInterface>hardware_interface/EffortJointInterface</hardwareInterface>
    </joint>
    <actuator name="LeftHip_actr">
      <hardwareInterface>hardware_interface/EffortJointInterface</hardwareInterface>
      <mechanicalReduction>1</mechanicalReduction>
    </actuator>
  </transmission>
  <transmission name="LeftKnee_tran">
    <type>transmission_interface/SimpleTransmission</type>
    <joint name="LeftKnee">
      <hardwareInterface>hardware_interface/EffortJointInterface</hardwareInterface>
    </joint>
    <actuator name="LeftKnee_actr">
      <hardwareInterface>hardware_interface/EffortJointInterface</hardwareInterface>
      <mechanicalReduction>1</mechanicalReduction>
    </actuator>
  </transmission>
  <transmission name="LeftAnkle_tran">
    <type>transmission_interface/SimpleTransmission</type>
    <joint name="LeftAnkle">
      <hardwareInterface>hardware_interface/EffortJointInterface</hardwareInterface>
    </joint>
    <actuator name="LeftAnkle_actr">
      <hardwareInterface>hardware_interface/EffortJointInterface</hardwareInterface>
      <mechanicalReduction>1</mechanicalReduction>
    </actuator>
  </transmission>
  <transmission name="LeftChest_tran">
    <type>transmission_interface/SimpleTransmission</type>
    <joint name="LeftChest">
      <hardwareInterface>hardware_interface/EffortJointInterface</hardwareInterface>
    </joint>
    <actuator name="LeftChest_actr">
      <hardwareInterface>hardware_interface/EffortJointInterface</hardwareInterface>
      <mechanicalReduction>1</mechanicalReduction>
    </actuator>
  </transmission>
  <transmission name="LeftShoulder_tran">
    <type>transmission_interface/SimpleTransmission</type>
    <joint name="LeftShoulder">
      <hardwareInterface>hardware_interface/EffortJointInterface</hardwareInterface>
    </joint>
    <actuator name="LeftShoulder_actr">
      <hardwareInterface>hardware_interface/EffortJointInterface</hardwareInterface>
      <mechanicalReduction>1</mechanicalReduction>
    </actuator>
  </transmission>
  <transmission name="LeftBicep_tran">
    <type>transmission_interface/SimpleTransmission</type>
    <joint name="LeftBicep">
      <hardwareInterface>hardware_interface/EffortJointInterface</hardwareInterface>
    </joint>
    <actuator name="LeftBicep_actr">
      <hardwareInterface>hardware_interface/EffortJointInterface</hardwareInterface>
      <mechanicalReduction>1</mechanicalReduction>
    </actuator>
  </transmission>
  <transmission name="LeftElbow_tran">
    <type>transmission_interface/SimpleTransmission</type>
    <joint name="LeftElbow">
      <hardwareInterface>hardware_interface/EffortJointInterface</hardwareInterface>
    </joint>
    <actuator name="LeftElbow_actr">
      <hardwareInterface>hardware_interface/EffortJointInterface</hardwareInterface>
      <mechanicalReduction>1</mechanicalReduction>
    </actuator>
  </transmission>
  <transmission name="RightShoulder_tran">
    <type>transmission_interface/SimpleTransmission</type>
    <joint name="RightShoulder">
      <hardwareInterface>hardware_interface/EffortJointInterface</hardwareInterface>
    </joint>
    <actuator name="RightShoulder_actr">
      <hardwareInterface>hardware_interface/EffortJointInterface</hardwareInterface>
      <mechanicalReduction>1</mechanicalReduction>
    </actuator>
  </transmission>
  <gazebo>
    <plugin filename="libgazebo_ros_control.so" name="control"/>
  </gazebo>
  <gazebo reference="base_link">
    <material>Gazebo/Silver</material>
    <mu1>0.2</mu1>
    <mu2>0.2</mu2>
    <selfCollide>true</selfCollide>
    <gravity>true</gravity>
  </gazebo>
  <gazebo reference="right_hip_servo_1">
    <material>Gazebo/Silver</material>
    <mu1>0.2</mu1>
    <mu2>0.2</mu2>
    <selfCollide>true</selfCollide>
  </gazebo>
  <gazebo reference="right_upper_leg_link_1">
    <material>Gazebo/Silver</material>
    <mu1>0.2</mu1>
    <mu2>0.2</mu2>
    <selfCollide>true</selfCollide>
  </gazebo>
  <gazebo reference="spine_link_1">
    <material>Gazebo/Silver</material>
    <mu1>0.2</mu1>
    <mu2>0.2</mu2>
    <selfCollide>true</selfCollide>
  </gazebo>
  <gazebo reference="spine_connector_link_1">
    <material>Gazebo/Silver</material>
    <mu1>0.2</mu1>
    <mu2>0.2</mu2>
    <selfCollide>true</selfCollide>
  </gazebo>
  <gazebo reference="chest_flat_back_link_1">
    <material>Gazebo/Silver</material>
    <mu1>0.2</mu1>
    <mu2>0.2</mu2>
    <selfCollide>true</selfCollide>
  </gazebo>
  <gazebo reference="right_torso_servo_1">
    <material>Gazebo/Silver</material>
    <mu1>0.2</mu1>
    <mu2>0.2</mu2>
    <selfCollide>true</selfCollide>
  </gazebo>
  <gazebo reference="neck_servo_1">
    <material>Gazebo/Silver</material>
    <mu1>0.2</mu1>
    <mu2>0.2</mu2>
    <selfCollide>true</selfCollide>
  </gazebo>
  <gazebo reference="right_shoulder_connector_link_1">
    <material>Gazebo/Silver</material>
    <mu1>0.2</mu1>
    <mu2>0.2</mu2>
    <selfCollide>true</selfCollide>
  </gazebo>
  <gazebo reference="neck_link_1">
    <material>Gazebo/Silver</material>
    <mu1>0.2</mu1>
    <mu2>0.2</mu2>
    <selfCollide>true</selfCollide>
  </gazebo>
  <gazebo reference="neck_connector_link_1">
    <material>Gazebo/Silver</material>
    <mu1>0.2</mu1>
    <mu2>0.2</mu2>
    <selfCollide>true</selfCollide>
  </gazebo>
  <gazebo reference="right_forearm_servo_1">
    <material>Gazebo/Silver</material>
    <mu1>0.2</mu1>
    <mu2>0.2</mu2>
    <selfCollide>true</selfCollide>
  </gazebo>
  <gazebo reference="right_elbow_servo_1">
    <material>Gazebo/Silver</material>
    <mu1>0.2</mu1>
    <mu2>0.2</mu2>
    <selfCollide>true</selfCollide>
  </gazebo>
  <gazebo reference="head_nod_servo_1">
    <material>Gazebo/Silver</material>
    <mu1>0.2</mu1>
    <mu2>0.2</mu2>
    <selfCollide>true</selfCollide>
  </gazebo>
  <gazebo reference="head_tilt_servo_1">
    <material>Gazebo/Silver</material>
    <mu1>0.2</mu1>
    <mu2>0.2</mu2>
    <selfCollide>true</selfCollide>
  </gazebo>
  <gazebo reference="chest_tilt_servo_1">
    <material>Gazebo/Silver</material>
    <mu1>0.2</mu1>
    <mu2>0.2</mu2>
    <selfCollide>true</selfCollide>
  </gazebo>
  <gazebo reference="chest_bend_servo_1">
    <material>Gazebo/Silver</material>
    <mu1>0.2</mu1>
    <mu2>0.2</mu2>
    <selfCollide>true</selfCollide>
  </gazebo>
  <gazebo reference="right_knee_Servo_1">
    <material>Gazebo/Silver</material>
    <mu1>0.2</mu1>
    <mu2>0.2</mu2>
    <selfCollide>true</selfCollide>
  </gazebo>
  <gazebo reference="right_forearm_link_1">
    <material>Gazebo/Silver</material>
    <mu1>0.2</mu1>
    <mu2>0.2</mu2>
    <selfCollide>true</selfCollide>
  </gazebo>
  <gazebo reference="right_lower_leg_link_1">
    <material>Gazebo/Silver</material>
    <mu1>0.2</mu1>
    <mu2>0.2</mu2>
    <selfCollide>true</selfCollide>
  </gazebo>
  <gazebo reference="right_ankle_servo_1">
    <material>Gazebo/Silver</material>
    <mu1>0.2</mu1>
    <mu2>0.2</mu2>
    <selfCollide>true</selfCollide>
  </gazebo>
  <gazebo reference="right_foot_link_1">
    <material>Gazebo/Silver</material>
    <mu1>0.2</mu1>
    <mu2>0.2</mu2>
    <selfCollide>true</selfCollide>
  </gazebo>
  <gazebo reference="head_connector_link_1">
    <material>Gazebo/Silver</material>
    <mu1>0.2</mu1>
    <mu2>0.2</mu2>
    <selfCollide>true</selfCollide>
  </gazebo>
  <gazebo reference="head_shell_1">
    <material>Gazebo/Silver</material>
    <mu1>0.2</mu1>
    <mu2>0.2</mu2>
    <selfCollide>true</selfCollide>
  </gazebo>
  <gazebo reference="eye_holder_1">
    <material>Gazebo/Silver</material>
    <mu1>0.2</mu1>
    <mu2>0.2</mu2>
    <selfCollide>true</selfCollide>
  </gazebo>
  <gazebo reference="right_hand_link_1">
    <material>Gazebo/Silver</material>
    <mu1>0.2</mu1>
    <mu2>0.2</mu2>
    <selfCollide>true</selfCollide>
  </gazebo>
  <gazebo reference="left_hip_servo_1">
    <material>Gazebo/Silver</material>
    <mu1>0.2</mu1>
    <mu2>0.2</mu2>
    <selfCollide>true</selfCollide>
  </gazebo>
  <gazebo reference="left_upper_leg_link_1">
    <material>Gazebo/Silver</material>
    <mu1>0.2</mu1>
    <mu2>0.2</mu2>
    <selfCollide>true</selfCollide>
  </gazebo>
  <gazebo reference="left_knee_servo_1">
    <material>Gazebo/Silver</material>
    <mu1>0.2</mu1>
    <mu2>0.2</mu2>
    <selfCollide>true</selfCollide>
  </gazebo>
  <gazebo reference="left_lower_leg_link_1">
    <material>Gazebo/Silver</material>
    <mu1>0.2</mu1>
    <mu2>0.2</mu2>
    <selfCollide>true</selfCollide>
  </gazebo>
  <gazebo reference="left_ankle_servo_1">
    <material>Gazebo/Silver</material>
    <mu1>0.2</mu1>
    <mu2>0.2</mu2>
    <selfCollide>true</selfCollide>
  </gazebo>
  <gazebo reference="left_foot_link_1">
    <material>Gazebo/Silver</material>
    <mu1>0.2</mu1>
    <mu2>0.2</mu2>
    <selfCollide>true</selfCollide>
  </gazebo>
  <gazebo reference="left_chest_servo_1">
    <material>Gazebo/Silver</material>
    <mu1>0.2</mu1>
    <mu2>0.2</mu2>
    <selfCollide>true</selfCollide>
  </gazebo>
  <gazebo reference="left_shoulder_connector_link_1">
    <material>Gazebo/Silver</material>
    <mu1>0.2</mu1>
    <mu2>0.2</mu2>
    <selfCollide>true</selfCollide>
  </gazebo>
  <gazebo reference="left_shoulder_link_1">
    <material>Gazebo/Silver</material>
    <mu1>0.2</mu1>
    <mu2>0.2</mu2>
    <selfCollide>true</selfCollide>
  </gazebo>
  <gazebo reference="left_shoulder_servo_1">
    <material>Gazebo/Silver</material>
    <mu1>0.2</mu1>
    <mu2>0.2</mu2>
    <selfCollide>true</selfCollide>
  </gazebo>
  <gazebo reference="left_forearm_servo_1">
    <material>Gazebo/Silver</material>
    <mu1>0.2</mu1>
    <mu2>0.2</mu2>
    <selfCollide>true</selfCollide>
  </gazebo>
  <gazebo reference="left_upper_arm_link_1">
    <material>Gazebo/Silver</material>
    <mu1>0.2</mu1>
    <mu2>0.2</mu2>
    <selfCollide>true</selfCollide>
  </gazebo>
  <gazebo reference="left_elbow_servo_1">
    <material>Gazebo/Silver</material>
    <mu1>0.2</mu1>
    <mu2>0.2</mu2>
    <selfCollide>true</selfCollide>
  </gazebo>
  <gazebo reference="left_forearm_link_1">
    <material>Gazebo/Silver</material>
    <mu1>0.2</mu1>
    <mu2>0.2</mu2>
    <selfCollide>true</selfCollide>
  </gazebo>
  <gazebo reference="right_shoulder_servo_1">
    <material>Gazebo/Silver</material>
    <mu1>0.2</mu1>
    <mu2>0.2</mu2>
    <selfCollide>true</selfCollide>
  </gazebo>
  <gazebo reference="right_shoulder_link_1">
    <material>Gazebo/Silver</material>
    <mu1>0.2</mu1>
    <mu2>0.2</mu2>
    <selfCollide>true</selfCollide>
  </gazebo>
  <gazebo reference="right_upper_arm_link_1">
    <material>Gazebo/Silver</material>
    <mu1>0.2</mu1>
    <mu2>0.2</mu2>
    <selfCollide>true</selfCollide>
  </gazebo>
  <gazebo reference="left_hand_link_1">
    <material>Gazebo/Silver</material>
    <mu1>0.2</mu1>
    <mu2>0.2</mu2>
    <selfCollide>true</selfCollide>
  </gazebo>
  <link name="base_link">
    <inertial>
      <origin rpy="0 0 0" xyz="-0.07082625526652554 -0.03194928238208809 -0.019152307850621764"/>
      <mass value="0.7432940286532945"/>
      <inertia ixx="0.000673" ixy="0.0" ixz="0.0" iyy="0.002458" iyz="1.6e-05" izz="0.002762"/>
    </inertial>
    <visual>
      <origin rpy="0 0 0" xyz="0 0 0"/>
      <geometry>
        <mesh filename="package://sammy_sim/meshes/base_link.stl" scale="0.001 0.001 0.001"/>
      </geometry>
      <material name="aluminum_anodized_glossy_red"/>
    </visual>
    <collision>
      <origin rpy="0 0 0" xyz="0 0 0"/>
      <geometry>
        <mesh filename="package://sammy_sim/meshes/base_link.stl" scale="0.001 0.001 0.001"/>
      </geometry>
    </collision>
  </link>
  <link name="right_hip_servo_1">
    <inertial>
      <origin rpy="0 0 0" xyz="0.002481291322172119 -0.005003130381428224 0.025165309780494884"/>
      <mass value="0.21176334532421678"/>
      <inertia ixx="3.7e-05" ixy="0.0" ixz="1e-06" iyy="5.5e-05" iyz="0.0" izz="3.2e-05"/>
    </inertial>
    <visual>
      <origin rpy="0 0 0" xyz="0.142326 0.053173 0.034835"/>
      <geometry>
        <mesh filename="package://sammy_sim/meshes/right_hip_servo_1.stl" scale="0.001 0.001 0.001"/>
      </geometry>
      <material name="steel_satin"/>
    </visual>
    <collision>
      <origin rpy="0 0 0" xyz="0.142326 0.053173 0.034835"/>
      <geometry>
        <mesh filename="package://sammy_sim/meshes/right_hip_servo_1.stl" scale="0.001 0.001 0.001"/>
      </geometry>
    </collision>
  </link>
  <link name="right_upper_leg_link_1">
    <inertial>
      <origin rpy="0 0 0" xyz="-0.012059766410574685 -0.08885860043236908 0.0028184890681623768"/>
      <mass value="0.40917868648388056"/>
      <inertia ixx="0.00143" ixy="0.000228" ixz="-1.7e-05" iyy="0.000342" iyz="9e-05" izz="0.001474"/>
    </inertial>
    <visual>
      <origin rpy="0 0 0" xyz="0.114126 0.058157 3.5e-05"/>
      <geometry>
        <mesh filename="package://sammy_sim/meshes/right_upper_leg_link_1.stl" scale="0.001 0.001 0.001"/>
      </geometry>
      <material name="aluminum_anodized_glossy_red"/>
    </visual>
    <collision>
      <origin rpy="0 0 0" xyz="0.114126 0.058157 3.5e-05"/>
      <geometry>
        <mesh filename="package://sammy_sim/meshes/right_upper_leg_link_1.stl" scale="0.001 0.001 0.001"/>
      </geometry>
    </collision>
  </link>
  <link name="spine_link_1">
    <inertial>
      <origin rpy="0 0 0" xyz="0.027489284084192933 -0.003069476744166643 0.08552595638707902"/>
      <mass value="0.2835281149906091"/>
      <inertia ixx="0.000818" ixy="-0.0" ixz="-5e-06" iyy="0.000939" iyz="-0.0" izz="0.000199"/>
    </inertial>
    <visual>
      <origin rpy="0 0 0" xyz="0.098076 -0.00104 0.011228"/>
      <geometry>
        <mesh filename="package://sammy_sim/meshes/spine_link_1.stl" scale="0.001 0.001 0.001"/>
      </geometry>
      <material name="aluminum_anodized_glossy_red"/>
    </visual>
    <collision>
      <origin rpy="0 0 0" xyz="0.098076 -0.00104 0.011228"/>
      <geometry>
        <mesh filename="package://sammy_sim/meshes/spine_link_1.stl" scale="0.001 0.001 0.001"/>
      </geometry>
    </collision>
  </link>
  <link name="spine_connector_link_1">
    <inertial>
      <origin rpy="0 0 0" xyz="0.01675681584463798 -0.009650168483376931 0.009601085275716875"/>
      <mass value="0.13622921421124207"/>
      <inertia ixx="9.4e-05" ixy="7e-06" ixz="-0.0" iyy="6.9e-05" iyz="1e-06" izz="5.6e-05"/>
    </inertial>
    <visual>
      <origin rpy="0 0 0" xyz="0.094476 -0.00104 -0.158772"/>
      <geometry>
        <mesh filename="package://sammy_sim/meshes/spine_connector_link_1.stl" scale="0.001 0.001 0.001"/>
      </geometry>
      <material name="aluminum_anodized_glossy_red"/>
    </visual>
    <collision>
      <origin rpy="0 0 0" xyz="0.094476 -0.00104 -0.158772"/>
      <geometry>
        <mesh filename="package://sammy_sim/meshes/spine_connector_link_1.stl" scale="0.001 0.001 0.001"/>
      </geometry>
    </collision>
  </link>
  <link name="chest_flat_back_link_1">
    <inertial>
      <origin rpy="0 0 0" xyz="-0.002535588326759944 -0.03199341507639908 0.045937153663593716"/>
      <mass value="1.4220810862541415"/>
      <inertia ixx="0.00109" ixy="7e-06" ixz="-0.000155" iyy="0.003622" iyz="-8.8e-05" izz="0.003918"/>
    </inertial>
    <visual>
      <origin rpy="0 0 0" xyz="0.072976 -0.013638 -0.158978"/>
      <geometry>
        <mesh filename="package://sammy_sim/meshes/chest_flat_back_link_1.stl" scale="0.001 0.001 0.001"/>
      </geometry>
      <material name="aluminum_anodized_glossy_red"/>
    </visual>
    <collision>
      <origin rpy="0 0 0" xyz="0.072976 -0.013638 -0.158978"/>
      <geometry>
        <mesh filename="package://sammy_sim/meshes/chest_flat_back_link_1.stl" scale="0.001 0.001 0.001"/>
      </geometry>
    </collision>
  </link>
  <link name="right_torso_servo_1">
    <inertial>
      <origin rpy="0 0 0" xyz="0.0033397704007420703 -0.020158249013521288 -0.00014458471670808493"/>
      <mass value="0.21176334532421678"/>
      <inertia ixx="3.8e-05" ixy="1e-06" ixz="-1e-06" iyy="3.2e-05" iyz="-0.0" izz="5.5e-05"/>
    </inertial>
    <visual>
      <origin rpy="0 0 0" xyz="0.144326 -0.007499 -0.205114"/>
      <geometry>
        <mesh filename="package://sammy_sim/meshes/right_torso_servo_1.stl" scale="0.001 0.001 0.001"/>
      </geometry>
      <material name="steel_satin"/>
    </visual>
    <collision>
      <origin rpy="0 0 0" xyz="0.144326 -0.007499 -0.205114"/>
      <geometry>
        <mesh filename="package://sammy_sim/meshes/right_torso_servo_1.stl" scale="0.001 0.001 0.001"/>
      </geometry>
    </collision>
  </link>
  <link name="neck_servo_1">
    <inertial>
      <origin rpy="0 0 0" xyz="0.00018535908888987762 -0.020400573066707867 -0.003674809220045566"/>
      <mass value="0.21176334532421678"/>
      <inertia ixx="5.5e-05" ixy="0.0" ixz="1e-06" iyy="3.2e-05" iyz="-2e-06" izz="3.7e-05"/>
    </inertial>
    <visual>
      <origin rpy="0 0 0" xyz="0.076851 -0.008449 -0.229897"/>
      <geometry>
        <mesh filename="package://sammy_sim/meshes/neck_servo_1.stl" scale="0.001 0.001 0.001"/>
      </geometry>
      <material name="steel_satin"/>
    </visual>
    <collision>
      <origin rpy="0 0 0" xyz="0.076851 -0.008449 -0.229897"/>
      <geometry>
        <mesh filename="package://sammy_sim/meshes/neck_servo_1.stl" scale="0.001 0.001 0.001"/>
      </geometry>
    </collision>
  </link>
  <link name="right_shoulder_connector_link_1">
    <inertial>
      <origin rpy="0 0 0" xyz="-0.007429845180324246 -0.010511108225469535 0.0010300480166418047"/>
      <mass value="0.08600606317174868"/>
      <inertia ixx="4.3e-05" ixy="0.0" ixz="-1e-06" iyy="2.3e-05" iyz="-1e-06" izz="4.8e-05"/>
    </inertial>
    <visual>
      <origin rpy="0 0 0" xyz="0.163566 0.002898 -0.203894"/>
      <geometry>
        <mesh filename="package://sammy_sim/meshes/right_shoulder_connector_link_1.stl" scale="0.001 0.001 0.001"/>
      </geometry>
      <material name="aluminum_anodized_glossy_red"/>
    </visual>
    <collision>
      <origin rpy="0 0 0" xyz="0.163566 0.002898 -0.203894"/>
      <geometry>
        <mesh filename="package://sammy_sim/meshes/right_shoulder_connector_link_1.stl" scale="0.001 0.001 0.001"/>
      </geometry>
    </collision>
  </link>
  <link name="neck_link_1">
    <inertial>
      <origin rpy="0 0 0" xyz="-0.0006156803230463193 -0.00917183010977465 0.007782299722202485"/>
      <mass value="0.10422527035422174"/>
      <inertia ixx="2.7e-05" ixy="-0.0" ixz="-1e-06" iyy="6.1e-05" iyz="1e-06" izz="5.9e-05"/>
    </inertial>
    <visual>
      <origin rpy="0 0 0" xyz="0.077901 0.00258 -0.248959"/>
      <geometry>
        <mesh filename="package://sammy_sim/meshes/neck_link_1.stl" scale="0.001 0.001 0.001"/>
      </geometry>
      <material name="aluminum_anodized_glossy_red"/>
    </visual>
    <collision>
      <origin rpy="0 0 0" xyz="0.077901 0.00258 -0.248959"/>
      <geometry>
        <mesh filename="package://sammy_sim/meshes/neck_link_1.stl" scale="0.001 0.001 0.001"/>
      </geometry>
    </collision>
  </link>
  <link name="neck_connector_link_1">
    <inertial>
      <origin rpy="0 0 0" xyz="-0.016967295129266542 0.009337510329268755 0.009276862421432164"/>
      <mass value="0.12808373101949122"/>
      <inertia ixx="8.8e-05" ixy="5e-06" ixz="3e-06" iyy="6.4e-05" iyz="1e-06" izz="5.1e-05"/>
    </inertial>
    <visual>
      <origin rpy="0 0 0" xyz="0.056371 0.018828 -0.276522"/>
      <geometry>
        <mesh filename="package://sammy_sim/meshes/neck_connector_link_1.stl" scale="0.001 0.001 0.001"/>
      </geometry>
      <material name="aluminum_anodized_glossy_red"/>
    </visual>
    <collision>
      <origin rpy="0 0 0" xyz="0.056371 0.018828 -0.276522"/>
      <geometry>
        <mesh filename="package://sammy_sim/meshes/neck_connector_link_1.stl" scale="0.001 0.001 0.001"/>
      </geometry>
    </collision>
  </link>
  <link name="right_forearm_servo_1">
    <inertial>
      <origin rpy="0 0 0" xyz="0.0011637270782630382 -0.009480236123684139 -0.022695250661135286"/>
      <mass value="0.21176334532421678"/>
      <inertia ixx="5.5e-05" ixy="-0.0" ixz="1e-06" iyy="3.2e-05" iyz="-2e-06" izz="3.7e-05"/>
    </inertial>
    <visual>
      <origin rpy="0 0 0" xyz="0.189045 0.004112 -0.165625"/>
      <geometry>
        <mesh filename="package://sammy_sim/meshes/right_forearm_servo_1.stl" scale="0.001 0.001 0.001"/>
      </geometry>
      <material name="steel_satin"/>
    </visual>
    <collision>
      <origin rpy="0 0 0" xyz="0.189045 0.004112 -0.165625"/>
      <geometry>
        <mesh filename="package://sammy_sim/meshes/right_forearm_servo_1.stl" scale="0.001 0.001 0.001"/>
      </geometry>
    </collision>
  </link>
  <link name="right_elbow_servo_1">
    <inertial>
      <origin rpy="0 0 0" xyz="0.008701072061462867 0.0006657592443442585 -0.02676462592411734"/>
      <mass value="0.21176334532421678"/>
      <inertia ixx="3.8e-05" ixy="0.0" ixz="-1e-06" iyy="5.5e-05" iyz="1e-06" izz="3.2e-05"/>
    </inertial>
    <visual>
      <origin rpy="0 0 0" xyz="0.19604 0.01323 -0.087804"/>
      <geometry>
        <mesh filename="package://sammy_sim/meshes/right_elbow_servo_1.stl" scale="0.001 0.001 0.001"/>
      </geometry>
      <material name="steel_satin"/>
    </visual>
    <collision>
      <origin rpy="0 0 0" xyz="0.19604 0.01323 -0.087804"/>
      <geometry>
        <mesh filename="package://sammy_sim/meshes/right_elbow_servo_1.stl" scale="0.001 0.001 0.001"/>
      </geometry>
    </collision>
  </link>
  <link name="head_nod_servo_1">
    <inertial>
      <origin rpy="0 0 0" xyz="0.0022420494590589812 -0.000186544010322396 0.020310052136532086"/>
      <mass value="0.21176334532421678"/>
      <inertia ixx="3.8e-05" ixy="-0.0" ixz="-1e-06" iyy="5.5e-05" iyz="0.0" izz="3.2e-05"/>
    </inertial>
    <visual>
      <origin rpy="0 0 0" xyz="0.086119 0.01873 -0.264483"/>
      <geometry>
        <mesh filename="package://sammy_sim/meshes/head_nod_servo_1.stl" scale="0.001 0.001 0.001"/>
      </geometry>
      <material name="steel_satin"/>
    </visual>
    <collision>
      <origin rpy="0 0 0" xyz="0.086119 0.01873 -0.264483"/>
      <geometry>
        <mesh filename="package://sammy_sim/meshes/head_nod_servo_1.stl" scale="0.001 0.001 0.001"/>
      </geometry>
    </collision>
  </link>
  <link name="head_tilt_servo_1">
    <inertial>
      <origin rpy="0 0 0" xyz="0.0010977480552400581 -0.0031566606986832627 -0.02015953208186827"/>
      <mass value="0.21176334532421678"/>
      <inertia ixx="5.5e-05" ixy="0.0" ixz="1e-06" iyy="3.7e-05" iyz="-1e-06" izz="3.2e-05"/>
    </inertial>
    <visual>
      <origin rpy="0 0 0" xyz="0.078528 -0.018884 -0.306314"/>
      <geometry>
        <mesh filename="package://sammy_sim/meshes/head_tilt_servo_1.stl" scale="0.001 0.001 0.001"/>
      </geometry>
      <material name="steel_satin"/>
    </visual>
    <collision>
      <origin rpy="0 0 0" xyz="0.078528 -0.018884 -0.306314"/>
      <geometry>
        <mesh filename="package://sammy_sim/meshes/head_tilt_servo_1.stl" scale="0.001 0.001 0.001"/>
      </geometry>
    </collision>
  </link>
  <link name="chest_tilt_servo_1">
    <inertial>
      <origin rpy="0 0 0" xyz="-3.297482133166052e-06 0.003014793136348691 0.020210653495040004"/>
      <mass value="0.21176334532421678"/>
      <inertia ixx="5.5e-05" ixy="0.0" ixz="-0.0" iyy="3.8e-05" iyz="-1e-06" izz="3.2e-05"/>
    </inertial>
    <visual>
      <origin rpy="0 0 0" xyz="0.072976 0.037185 -0.147744"/>
      <geometry>
        <mesh filename="package://sammy_sim/meshes/chest_tilt_servo_1.stl" scale="0.001 0.001 0.001"/>
      </geometry>
      <material name="steel_satin"/>
    </visual>
    <collision>
      <origin rpy="0 0 0" xyz="0.072976 0.037185 -0.147744"/>
      <geometry>
        <mesh filename="package://sammy_sim/meshes/chest_tilt_servo_1.stl" scale="0.001 0.001 0.001"/>
      </geometry>
    </collision>
  </link>
  <link name="chest_bend_servo_1">
    <inertial>
      <origin rpy="0 0 0" xyz="-0.003345730508966388 -0.00033317739609285625 0.02015589547244806"/>
      <mass value="0.21176334532421678"/>
      <inertia ixx="3.7e-05" ixy="-0.0" ixz="1e-06" iyy="5.5e-05" iyz="0.0" izz="3.2e-05"/>
    </inertial>
    <visual>
      <origin rpy="0 0 0" xyz="0.063116 -0.00121 -0.148373"/>
      <geometry>
        <mesh filename="package://sammy_sim/meshes/chest_bend_servo_1.stl" scale="0.001 0.001 0.001"/>
      </geometry>
      <material name="steel_satin"/>
    </visual>
    <collision>
      <origin rpy="0 0 0" xyz="0.063116 -0.00121 -0.148373"/>
      <geometry>
        <mesh filename="package://sammy_sim/meshes/chest_bend_servo_1.stl" scale="0.001 0.001 0.001"/>
      </geometry>
    </collision>
  </link>
  <link name="right_knee_Servo_1">
    <inertial>
      <origin rpy="0 0 0" xyz="0.007226713395017487 -0.02720726124861203 -2.851864765144235e-06"/>
      <mass value="0.21176334532421678"/>
      <inertia ixx="3.8e-05" ixy="-1e-06" ixz="0.0" iyy="3.2e-05" iyz="-0.0" izz="5.5e-05"/>
    </inertial>
    <visual>
      <origin rpy="0 0 0" xyz="0.125812 0.202533 3.1e-05"/>
      <geometry>
        <mesh filename="package://sammy_sim/meshes/right_knee_Servo_1.stl" scale="0.001 0.001 0.001"/>
      </geometry>
      <material name="steel_satin"/>
    </visual>
    <collision>
      <origin rpy="0 0 0" xyz="0.125812 0.202533 3.1e-05"/>
      <geometry>
        <mesh filename="package://sammy_sim/meshes/right_knee_Servo_1.stl" scale="0.001 0.001 0.001"/>
      </geometry>
    </collision>
  </link>
  <link name="right_forearm_link_1">
    <inertial>
      <origin rpy="0 0 0" xyz="0.0210300559635567 -0.048396725049772694 -0.013155628399828798"/>
      <mass value="0.223947903676007"/>
      <inertia ixx="0.000414" ixy="-4.1e-05" ixz="1e-06" iyy="7.1e-05" iyz="9e-06" izz="0.000435"/>
    </inertial>
    <visual>
      <origin rpy="0 0 0" xyz="0.209219 0.012123 -0.049754"/>
      <geometry>
        <mesh filename="package://sammy_sim/meshes/right_forearm_link_1.stl" scale="0.001 0.001 0.001"/>
      </geometry>
      <material name="aluminum_anodized_glossy_red"/>
    </visual>
    <collision>
      <origin rpy="0 0 0" xyz="0.209219 0.012123 -0.049754"/>
      <geometry>
        <mesh filename="package://sammy_sim/meshes/right_forearm_link_1.stl" scale="0.001 0.001 0.001"/>
      </geometry>
    </collision>
  </link>
  <link name="right_lower_leg_link_1">
    <inertial>
      <origin rpy="0 0 0" xyz="0.025576048251875816 -0.004154090144054601 -0.07206975551478847"/>
      <mass value="0.36679329720363735"/>
      <inertia ixx="0.001367" ixy="0.0" ixz="-7e-06" iyy="0.001362" iyz="7.2e-05" izz="0.000241"/>
    </inertial>
    <visual>
      <origin rpy="0 0 0" xyz="0.14105 0.239822 3.1e-05"/>
      <geometry>
        <mesh filename="package://sammy_sim/meshes/right_lower_leg_link_1.stl" scale="0.001 0.001 0.001"/>
      </geometry>
      <material name="aluminum_anodized_glossy_red"/>
    </visual>
    <collision>
      <origin rpy="0 0 0" xyz="0.14105 0.239822 3.1e-05"/>
      <geometry>
        <mesh filename="package://sammy_sim/meshes/right_lower_leg_link_1.stl" scale="0.001 0.001 0.001"/>
      </geometry>
    </collision>
  </link>
  <link name="right_ankle_servo_1">
    <inertial>
      <origin rpy="0 0 0" xyz="0.0072256747334668164 0.00016261363833144915 -0.027207205980904287"/>
      <mass value="0.21176334532421678"/>
      <inertia ixx="3.8e-05" ixy="-0.0" ixz="-1e-06" iyy="5.5e-05" iyz="-0.0" izz="3.2e-05"/>
    </inertial>
    <visual>
      <origin rpy="0 0 0" xyz="0.127528 0.240675 0.141131"/>
      <geometry>
        <mesh filename="package://sammy_sim/meshes/right_ankle_servo_1.stl" scale="0.001 0.001 0.001"/>
      </geometry>
      <material name="steel_satin"/>
    </visual>
    <collision>
      <origin rpy="0 0 0" xyz="0.127528 0.240675 0.141131"/>
      <geometry>
        <mesh filename="package://sammy_sim/meshes/right_ankle_servo_1.stl" scale="0.001 0.001 0.001"/>
      </geometry>
    </collision>
  </link>
  <link name="right_foot_link_1">
    <inertial>
      <origin rpy="0 0 0" xyz="0.024304081278909623 -0.025963497307866124 -0.02238706199927748"/>
      <mass value="0.049173423820837"/>
      <inertia ixx="8.6e-05" ixy="-1e-06" ixz="-0.0" iyy="2.1e-05" iyz="-4e-06" izz="9.5e-05"/>
    </inertial>
    <visual>
      <origin rpy="0 0 0" xyz="0.142761 0.24101 0.17842"/>
      <geometry>
        <mesh filename="package://sammy_sim/meshes/right_foot_link_1.stl" scale="0.001 0.001 0.001"/>
      </geometry>
      <material name="aluminum_anodized_glossy_red"/>
    </visual>
    <collision>
      <origin rpy="0 0 0" xyz="0.142761 0.24101 0.17842"/>
      <geometry>
        <mesh filename="package://sammy_sim/meshes/right_foot_link_1.stl" scale="0.001 0.001 0.001"/>
      </geometry>
    </collision>
  </link>
  <link name="head_connector_link_1">
    <inertial>
      <origin rpy="0 0 0" xyz="-0.0019515334621435093 0.024568580797175898 0.03680093671068313"/>
      <mass value="0.2947915476168725"/>
      <inertia ixx="0.000226" ixy="0.0" ixz="3e-06" iyy="8.9e-05" iyz="-1e-06" izz="0.000167"/>
    </inertial>
    <visual>
      <origin rpy="0 0 0" xyz="0.077934 0.031517 -0.295457"/>
      <geometry>
        <mesh filename="package://sammy_sim/meshes/head_connector_link_1.stl" scale="0.001 0.001 0.001"/>
      </geometry>
      <material name="aluminum_anodized_glossy_red"/>
    </visual>
    <collision>
      <origin rpy="0 0 0" xyz="0.077934 0.031517 -0.295457"/>
      <geometry>
        <mesh filename="package://sammy_sim/meshes/head_connector_link_1.stl" scale="0.001 0.001 0.001"/>
      </geometry>
    </collision>
  </link>
  <link name="head_shell_1">
    <inertial>
      <origin rpy="0 0 0" xyz="-0.002537603216984652 -0.0023374838108376865 -0.028845612103224116"/>
      <mass value="2.5619159764134545"/>
      <inertia ixx="0.009465" ixy="0.000233" ixz="-0.000365" iyy="0.014004" iyz="-0.000391" izz="0.011474"/>
    </inertial>
    <visual>
      <origin rpy="0 0 0" xyz="0.081372 0.022508 -0.35845"/>
      <geometry>
        <mesh filename="package://sammy_sim/meshes/head_shell_1.stl" scale="0.001 0.001 0.001"/>
      </geometry>
      <material name="aluminum_anodized_glossy_red"/>
    </visual>
    <collision>
      <origin rpy="0 0 0" xyz="0.081372 0.022508 -0.35845"/>
      <geometry>
        <mesh filename="package://sammy_sim/meshes/head_shell_1.stl" scale="0.001 0.001 0.001"/>
      </geometry>
    </collision>
  </link>
  <link name="eye_holder_1">
    <inertial>
      <origin rpy="0 0 0" xyz="-0.00014867771837191734 -0.006635346109058721 0.0027334680345112994"/>
      <mass value="0.161483244889915"/>
      <inertia ixx="6.4e-05" ixy="0.0" ixz="-1.6e-05" iyy="0.000324" iyz="1e-06" izz="0.00026"/>
    </inertial>
    <visual>
      <origin rpy="0 0 0" xyz="0.079005 0.038806 -0.315067"/>
      <geometry>
        <mesh filename="package://sammy_sim/meshes/eye_holder_1.stl" scale="0.001 0.001 0.001"/>
      </geometry>
      <material name="led_green"/>
    </visual>
    <collision>
      <origin rpy="0 0 0" xyz="0.079005 0.038806 -0.315067"/>
      <geometry>
        <mesh filename="package://sammy_sim/meshes/eye_holder_1.stl" scale="0.001 0.001 0.001"/>
      </geometry>
    </collision>
  </link>
  <link name="right_hand_link_1">
    <inertial>
      <origin rpy="0 0 0" xyz="0.0009476458038502333 -0.02607058365007775 -0.0005324268303244228"/>
      <mass value="0.31126953608135455"/>
      <inertia ixx="0.00012" ixy="-5e-06" ixz="-4e-06" iyy="6.7e-05" iyz="-5e-06" izz="7.3e-05"/>
    </inertial>
    <visual>
      <origin rpy="0 0 0" xyz="0.195261 0.135603 -0.037337"/>
      <geometry>
        <mesh filename="package://sammy_sim/meshes/right_hand_link_1.stl" scale="0.001 0.001 0.001"/>
      </geometry>
      <material name="steel_satin"/>
    </visual>
    <collision>
      <origin rpy="0 0 0" xyz="0.195261 0.135603 -0.037337"/>
      <geometry>
        <mesh filename="package://sammy_sim/meshes/right_hand_link_1.stl" scale="0.001 0.001 0.001"/>
      </geometry>
    </collision>
  </link>
  <link name="left_hip_servo_1">
    <inertial>
      <origin rpy="0 0 0" xyz="-0.007227347582615037 -0.00500313038275578 0.025012140237310593"/>
      <mass value="0.21176334631614013"/>
      <inertia ixx="3.8e-05" ixy="-0.0" ixz="-1e-06" iyy="5.5e-05" iyz="0.0" izz="3.2e-05"/>
    </inertial>
    <visual>
      <origin rpy="0 0 0" xyz="-0.006774 0.053173 0.034835"/>
      <geometry>
        <mesh filename="package://sammy_sim/meshes/left_hip_servo_1.stl" scale="0.001 0.001 0.001"/>
      </geometry>
      <material name="steel_satin"/>
    </visual>
    <collision>
      <origin rpy="0 0 0" xyz="-0.006774 0.053173 0.034835"/>
      <geometry>
        <mesh filename="package://sammy_sim/meshes/left_hip_servo_1.stl" scale="0.001 0.001 0.001"/>
      </geometry>
    </collision>
  </link>
  <link name="left_upper_leg_link_1">
    <inertial>
      <origin rpy="0 0 0" xyz="0.012059255237433914 -0.0888586004276511 0.002818489081157595"/>
      <mass value="0.40917868626135256"/>
      <inertia ixx="0.00143" ixy="-0.000228" ixz="1.7e-05" iyy="0.000342" iyz="9e-05" izz="0.001474"/>
    </inertial>
    <visual>
      <origin rpy="0 0 0" xyz="0.027526 0.058157 3.5e-05"/>
      <geometry>
        <mesh filename="package://sammy_sim/meshes/left_upper_leg_link_1.stl" scale="0.001 0.001 0.001"/>
      </geometry>
      <material name="aluminum_anodized_glossy_red"/>
    </visual>
    <collision>
      <origin rpy="0 0 0" xyz="0.027526 0.058157 3.5e-05"/>
      <geometry>
        <mesh filename="package://sammy_sim/meshes/left_upper_leg_link_1.stl" scale="0.001 0.001 0.001"/>
      </geometry>
    </collision>
  </link>
  <link name="left_knee_servo_1">
    <inertial>
      <origin rpy="0 0 0" xyz="-0.00722722450540552 -0.02501240463156787 -0.0050025490049248975"/>
      <mass value="0.21176334631614013"/>
      <inertia ixx="3.8e-05" ixy="1e-06" ixz="-0.0" iyy="3.2e-05" iyz="-0.0" izz="5.5e-05"/>
    </inertial>
    <visual>
      <origin rpy="0 0 0" xyz="0.01584 0.205498 -0.004485"/>
      <geometry>
        <mesh filename="package://sammy_sim/meshes/left_knee_servo_1.stl" scale="0.001 0.001 0.001"/>
      </geometry>
      <material name="steel_satin"/>
    </visual>
    <collision>
      <origin rpy="0 0 0" xyz="0.01584 0.205498 -0.004485"/>
      <geometry>
        <mesh filename="package://sammy_sim/meshes/left_knee_servo_1.stl" scale="0.001 0.001 0.001"/>
      </geometry>
    </collision>
  </link>
  <link name="left_lower_leg_link_1">
    <inertial>
      <origin rpy="0 0 0" xyz="-0.025575561672839447 -0.004154235144911644 -0.0720694421446251"/>
      <mass value="0.36679334835639393"/>
      <inertia ixx="0.001367" ixy="-0.0" ixz="7e-06" iyy="0.001362" iyz="7.2e-05" izz="0.000241"/>
    </inertial>
    <visual>
      <origin rpy="0 0 0" xyz="0.000603 0.240592 0.000515"/>
      <geometry>
        <mesh filename="package://sammy_sim/meshes/left_lower_leg_link_1.stl" scale="0.001 0.001 0.001"/>
      </geometry>
      <material name="aluminum_anodized_glossy_red"/>
    </visual>
    <collision>
      <origin rpy="0 0 0" xyz="0.000603 0.240592 0.000515"/>
      <geometry>
        <mesh filename="package://sammy_sim/meshes/left_lower_leg_link_1.stl" scale="0.001 0.001 0.001"/>
      </geometry>
    </collision>
  </link>
  <link name="left_ankle_servo_1">
    <inertial>
      <origin rpy="0 0 0" xyz="-0.0071150672116101175 0.005161336721664661 -0.025011869198598102"/>
      <mass value="0.21176334631614013"/>
      <inertia ixx="3.8e-05" ixy="0.0" ixz="1e-06" iyy="5.5e-05" iyz="-0.0" izz="3.2e-05"/>
    </inertial>
    <visual>
      <origin rpy="0 0 0" xyz="0.014223 0.245894 0.143915"/>
      <geometry>
        <mesh filename="package://sammy_sim/meshes/left_ankle_servo_1.stl" scale="0.001 0.001 0.001"/>
      </geometry>
      <material name="steel_satin"/>
    </visual>
    <collision>
      <origin rpy="0 0 0" xyz="0.014223 0.245894 0.143915"/>
      <geometry>
        <mesh filename="package://sammy_sim/meshes/left_ankle_servo_1.stl" scale="0.001 0.001 0.001"/>
      </geometry>
    </collision>
  </link>
  <link name="left_foot_link_1">
    <inertial>
      <origin rpy="0 0 0" xyz="-0.02430412083471322 -0.025963681026029833 -0.02238683587299406"/>
      <mass value="0.049172133299005855"/>
      <inertia ixx="8.6e-05" ixy="1e-06" ixz="0.0" iyy="2.1e-05" iyz="-4e-06" izz="9.5e-05"/>
    </inertial>
    <visual>
      <origin rpy="0 0 0" xyz="-0.001121 0.241231 0.179009"/>
      <geometry>
        <mesh filename="package://sammy_sim/meshes/left_foot_link_1.stl" scale="0.001 0.001 0.001"/>
      </geometry>
      <material name="aluminum_anodized_glossy_red"/>
    </visual>
    <collision>
      <origin rpy="0 0 0" xyz="-0.001121 0.241231 0.179009"/>
      <geometry>
        <mesh filename="package://sammy_sim/meshes/left_foot_link_1.stl" scale="0.001 0.001 0.001"/>
      </geometry>
    </collision>
  </link>
  <link name="left_chest_servo_1">
    <inertial>
      <origin rpy="0 0 0" xyz="-0.004327263857634777 -0.02432517505628404 0.0043760383506855904"/>
      <mass value="0.21176334631614013"/>
      <inertia ixx="3.7e-05" ixy="-2e-06" ixz="-1e-06" iyy="3.2e-05" iyz="-0.0" izz="5.5e-05"/>
    </inertial>
    <visual>
      <origin rpy="0 0 0" xyz="0.006803 -0.011678 -0.207587"/>
      <geometry>
        <mesh filename="package://sammy_sim/meshes/left_chest_servo_1.stl" scale="0.001 0.001 0.001"/>
      </geometry>
      <material name="steel_satin"/>
    </visual>
    <collision>
      <origin rpy="0 0 0" xyz="0.006803 -0.011678 -0.207587"/>
      <geometry>
        <mesh filename="package://sammy_sim/meshes/left_chest_servo_1.stl" scale="0.001 0.001 0.001"/>
      </geometry>
    </collision>
  </link>
  <link name="left_shoulder_connector_link_1">
    <inertial>
      <origin rpy="0 0 0" xyz="0.006941666517271773 -0.010717681058682451 0.0019231857406032948"/>
      <mass value="0.08600611455643586"/>
      <inertia ixx="4.3e-05" ixy="-1e-06" ixz="0.0" iyy="2.3e-05" iyz="-1e-06" izz="4.8e-05"/>
    </inertial>
    <visual>
      <origin rpy="0 0 0" xyz="-0.011723 0.003586 -0.213356"/>
      <geometry>
        <mesh filename="package://sammy_sim/meshes/left_shoulder_connector_link_1.stl" scale="0.001 0.001 0.001"/>
      </geometry>
      <material name="aluminum_anodized_glossy_red"/>
    </visual>
    <collision>
      <origin rpy="0 0 0" xyz="-0.011723 0.003586 -0.213356"/>
      <geometry>
        <mesh filename="package://sammy_sim/meshes/left_shoulder_connector_link_1.stl" scale="0.001 0.001 0.001"/>
      </geometry>
    </collision>
  </link>
  <link name="left_shoulder_link_1">
    <inertial>
      <origin rpy="0 0 0" xyz="0.0004574330363138063 -0.01624405264047675 -0.01525731426357027"/>
      <mass value="0.10206157321103919"/>
      <inertia ixx="4.9e-05" ixy="-0.0" ixz="1e-06" iyy="4.1e-05" iyz="-0.0" izz="2.5e-05"/>
    </inertial>
    <visual>
      <origin rpy="0 0 0" xyz="-0.039521 -0.009055 -0.215033"/>
      <geometry>
        <mesh filename="package://sammy_sim/meshes/left_shoulder_link_1.stl" scale="0.001 0.001 0.001"/>
      </geometry>
      <material name="aluminum_anodized_glossy_red"/>
    </visual>
    <collision>
      <origin rpy="0 0 0" xyz="-0.039521 -0.009055 -0.215033"/>
      <geometry>
        <mesh filename="package://sammy_sim/meshes/left_shoulder_link_1.stl" scale="0.001 0.001 0.001"/>
      </geometry>
    </collision>
  </link>
  <link name="left_shoulder_servo_1">
    <inertial>
      <origin rpy="0 0 0" xyz="-0.0035832666810457214 0.0045609042369381715 -0.024411340110060548"/>
      <mass value="0.21176334631614013"/>
      <inertia ixx="5.5e-05" ixy="-0.0" ixz="1e-06" iyy="3.7e-05" iyz="2e-06" izz="3.2e-05"/>
    </inertial>
    <visual>
      <origin rpy="0 0 0" xyz="-0.043023 0.022288 -0.229786"/>
      <geometry>
        <mesh filename="package://sammy_sim/meshes/left_shoulder_servo_1.stl" scale="0.001 0.001 0.001"/>
      </geometry>
      <material name="steel_satin"/>
    </visual>
    <collision>
      <origin rpy="0 0 0" xyz="-0.043023 0.022288 -0.229786"/>
      <geometry>
        <mesh filename="package://sammy_sim/meshes/left_shoulder_servo_1.stl" scale="0.001 0.001 0.001"/>
      </geometry>
    </collision>
  </link>
  <link name="left_forearm_servo_1">
    <inertial>
      <origin rpy="0 0 0" xyz="0.0010215600599516664 -0.009218205790410303 -0.02280989316346624"/>
      <mass value="0.21176334631614013"/>
      <inertia ixx="5.5e-05" ixy="-0.0" ixz="1e-06" iyy="3.2e-05" iyz="-2e-06" izz="3.7e-05"/>
    </inertial>
    <visual>
      <origin rpy="0 0 0" xyz="-0.041149 0.004535 -0.178762"/>
      <geometry>
        <mesh filename="package://sammy_sim/meshes/left_forearm_servo_1.stl" scale="0.001 0.001 0.001"/>
      </geometry>
      <material name="steel_satin"/>
    </visual>
    <collision>
      <origin rpy="0 0 0" xyz="-0.041149 0.004535 -0.178762"/>
      <geometry>
        <mesh filename="package://sammy_sim/meshes/left_forearm_servo_1.stl" scale="0.001 0.001 0.001"/>
      </geometry>
    </collision>
  </link>
  <link name="left_upper_arm_link_1">
    <inertial>
      <origin rpy="0 0 0" xyz="-0.003080371875684558 0.020839878132729965 -0.024949022930470466"/>
      <mass value="0.2528063544081857"/>
      <inertia ixx="0.000322" ixy="-2e-06" ixz="1.2e-05" iyy="0.000295" iyz="3.1e-05" izz="0.00014"/>
    </inertial>
    <visual>
      <origin rpy="0 0 0" xyz="-0.046419 0.03908 -0.159309"/>
      <geometry>
        <mesh filename="package://sammy_sim/meshes/left_upper_arm_link_1.stl" scale="0.001 0.001 0.001"/>
      </geometry>
      <material name="aluminum_anodized_glossy_red"/>
    </visual>
    <collision>
      <origin rpy="0 0 0" xyz="-0.046419 0.03908 -0.159309"/>
      <geometry>
        <mesh filename="package://sammy_sim/meshes/left_upper_arm_link_1.stl" scale="0.001 0.001 0.001"/>
      </geometry>
    </collision>
  </link>
  <link name="left_elbow_servo_1">
    <inertial>
      <origin rpy="0 0 0" xyz="-0.005943812340255039 -0.0038761511688201605 -0.025543139270668272"/>
      <mass value="0.21176334631614013"/>
      <inertia ixx="3.7e-05" ixy="0.0" ixz="2e-06" iyy="5.5e-05" iyz="1e-06" izz="3.2e-05"/>
    </inertial>
    <visual>
      <origin rpy="0 0 0" xyz="-0.056505 0.008014 -0.099915"/>
      <geometry>
        <mesh filename="package://sammy_sim/meshes/left_elbow_servo_1.stl" scale="0.001 0.001 0.001"/>
      </geometry>
      <material name="steel_satin"/>
    </visual>
    <collision>
      <origin rpy="0 0 0" xyz="-0.056505 0.008014 -0.099915"/>
      <geometry>
        <mesh filename="package://sammy_sim/meshes/left_elbow_servo_1.stl" scale="0.001 0.001 0.001"/>
      </geometry>
    </collision>
  </link>
  <link name="left_forearm_link_1">
    <inertial>
      <origin rpy="0 0 0" xyz="-0.020926068857672057 -0.047580227820267836 -0.01599280522179858"/>
      <mass value="0.2239481878604043"/>
      <inertia ixx="0.000417" ixy="3e-05" ixz="-3e-06" iyy="6.9e-05" iyz="8e-06" izz="0.000435"/>
    </inertial>
    <visual>
      <origin rpy="0 0 0" xyz="-0.073541 0.012025 -0.065528"/>
      <geometry>
        <mesh filename="package://sammy_sim/meshes/left_forearm_link_1.stl" scale="0.001 0.001 0.001"/>
      </geometry>
      <material name="aluminum_anodized_glossy_red"/>
    </visual>
    <collision>
      <origin rpy="0 0 0" xyz="-0.073541 0.012025 -0.065528"/>
      <geometry>
        <mesh filename="package://sammy_sim/meshes/left_forearm_link_1.stl" scale="0.001 0.001 0.001"/>
      </geometry>
    </collision>
  </link>
  <link name="right_shoulder_servo_1">
    <inertial>
      <origin rpy="0 0 0" xyz="0.0006710703166474541 0.022927314816553954 -0.008954085138101892"/>
      <mass value="0.21176334532421678"/>
      <inertia ixx="5.5e-05" ixy="-0.0" ixz="1e-06" iyy="3.7e-05" iyz="2e-06" izz="3.2e-05"/>
    </inertial>
    <visual>
      <origin rpy="0 0 0" xyz="0.191312 0.039928 -0.201347"/>
      <geometry>
        <mesh filename="package://sammy_sim/meshes/right_shoulder_servo_1.stl" scale="0.001 0.001 0.001"/>
      </geometry>
      <material name="steel_satin"/>
    </visual>
    <collision>
      <origin rpy="0 0 0" xyz="0.191312 0.039928 -0.201347"/>
      <geometry>
        <mesh filename="package://sammy_sim/meshes/right_shoulder_servo_1.stl" scale="0.001 0.001 0.001"/>
      </geometry>
    </collision>
  </link>
  <link name="right_shoulder_link_1">
    <inertial>
      <origin rpy="0 0 0" xyz="0.006747272366916385 0.014606767558301125 -0.029647607415213106"/>
      <mass value="0.1020615316178321"/>
      <inertia ixx="4.9e-05" ixy="-0.0" ixz="1e-06" iyy="4.1e-05" iyz="-1e-06" izz="2.5e-05"/>
    </inertial>
    <visual>
      <origin rpy="0 0 0" xyz="0.196987 0.021132 -0.216314"/>
      <geometry>
        <mesh filename="package://sammy_sim/meshes/right_shoulder_link_1.stl" scale="0.001 0.001 0.001"/>
      </geometry>
      <material name="aluminum_anodized_glossy_red"/>
    </visual>
    <collision>
      <origin rpy="0 0 0" xyz="0.196987 0.021132 -0.216314"/>
      <geometry>
        <mesh filename="package://sammy_sim/meshes/right_shoulder_link_1.stl" scale="0.001 0.001 0.001"/>
      </geometry>
    </collision>
  </link>
  <link name="right_upper_arm_link_1">
    <inertial>
      <origin rpy="0 0 0" xyz="0.006414022054376578 0.02040941658318538 -0.02466792977782424"/>
      <mass value="0.2528063543948451"/>
      <inertia ixx="0.000322" ixy="-2e-06" ixz="9e-06" iyy="0.000296" iyz="2.9e-05" izz="0.000139"/>
    </inertial>
    <visual>
      <origin rpy="0 0 0" xyz="0.19326 0.038733 -0.146051"/>
      <geometry>
        <mesh filename="package://sammy_sim/meshes/right_upper_arm_link_1.stl" scale="0.001 0.001 0.001"/>
      </geometry>
      <material name="aluminum_anodized_glossy_red"/>
    </visual>
    <collision>
      <origin rpy="0 0 0" xyz="0.19326 0.038733 -0.146051"/>
      <geometry>
        <mesh filename="package://sammy_sim/meshes/right_upper_arm_link_1.stl" scale="0.001 0.001 0.001"/>
      </geometry>
    </collision>
  </link>
  <link name="left_hand_link_1">
    <inertial>
      <origin rpy="0 0 0" xyz="-0.001668944532478886 -0.026021615317858404 -0.0009760476294174772"/>
      <mass value="0.31126953608135455"/>
      <inertia ixx="0.000119" ixy="4e-06" ixz="9e-06" iyy="6.7e-05" iyz="-4e-06" izz="7.4e-05"/>
    </inertial>
    <visual>
      <origin rpy="0 0 0" xyz="-0.0573 0.134877 -0.050043"/>
      <geometry>
        <mesh filename="package://sammy_sim/meshes/left_hand_link_1.stl" scale="0.001 0.001 0.001"/>
      </geometry>
      <material name="steel_satin"/>
    </visual>
    <collision>
      <origin rpy="0 0 0" xyz="-0.0573 0.134877 -0.050043"/>
      <geometry>
        <mesh filename="package://sammy_sim/meshes/left_hand_link_1.stl" scale="0.001 0.001 0.001"/>
      </geometry>
    </collision>
  </link>
  <joint name="Rigid 1" type="fixed">
    <origin rpy="0 0 0" xyz="-0.142326 -0.053173 -0.034835"/>
    <parent link="base_link"/>
    <child link="right_hip_servo_1"/>
  </joint>
  <joint name="RightHip" type="revolute">
    <origin rpy="0 0 0" xyz="-0.114126 -0.058157 -3.5e-05"/>
    <parent link="base_link"/>
    <child link="right_upper_leg_link_1"/>
    <axis xyz="1.0 -0.0 0.0"/>
    <limit effort="100" lower="4.18879" upper="6.283185" velocity="100"/>
  </joint>
  <joint name="Rigid 3" type="fixed">
    <origin rpy="0 0 0" xyz="-0.098076 0.00104 -0.011228"/>
    <parent link="base_link"/>
    <child link="spine_link_1"/>
  </joint>
  <joint name="TorsoBow" type="revolute">
    <origin rpy="0 0 0" xyz="0.0036 0.0 0.17"/>
    <parent link="spine_link_1"/>
    <child link="spine_connector_link_1"/>
    <axis xyz="-1.0 0.0 -0.0"/>
    <limit effort="100" lower="4.18879" upper="6.283185" velocity="100"/>
  </joint>
  <joint name="TorsoTilt" type="continuous">
    <origin rpy="0 0 0" xyz="0.0215 0.012598 0.000206"/>
    <parent link="spine_connector_link_1"/>
    <child link="chest_flat_back_link_1"/>
    <axis xyz="-0.0 -0.999866 -0.016383"/>
  </joint>
  <joint name="Rigid 6" type="fixed">
    <origin rpy="0 0 0" xyz="-0.07135 -0.006139 0.046136"/>
    <parent link="chest_flat_back_link_1"/>
    <child link="right_torso_servo_1"/>
  </joint>
  <joint name="Rigid 7" type="fixed">
    <origin rpy="0 0 0" xyz="-0.003875 -0.005189 0.070919"/>
    <parent link="chest_flat_back_link_1"/>
    <child link="neck_servo_1"/>
  </joint>
  <joint name="RightChest" type="revolute">
    <origin rpy="0 0 0" xyz="-0.01924 -0.010397 -0.00122"/>
    <parent link="right_torso_servo_1"/>
    <child link="right_shoulder_connector_link_1"/>
    <axis xyz="-0.99849 0.007873 -0.05437"/>
    <limit effort="100" lower="4.18879" upper="6.283185" velocity="100"/>
  </joint>
  <joint name="HeadTurn" type="revolute">
    <origin rpy="0 0 0" xyz="-0.00105 -0.011029 0.019062"/>
    <parent link="neck_servo_1"/>
    <child link="neck_link_1"/>
    <axis xyz="-0.054492 -0.009378 0.99847"/>
    <limit effort="100" lower="0.0" upper="4.18879" velocity="100"/>
  </joint>
  <joint name="HeadNod" type="revolute">
    <origin rpy="0 0 0" xyz="0.02153 -0.016248 0.027563"/>
    <parent link="neck_link_1"/>
    <child link="neck_connector_link_1"/>
    <axis xyz="0.998514 1.2e-05 0.054494"/>
    <limit effort="100" lower="4.18879" upper="6.283185" velocity="100"/>
  </joint>
  <joint name="RightBicep" type="revolute">
    <origin rpy="0 0 0" xyz="0.007942 0.01702 -0.050689"/>
    <parent link="right_shoulder_link_1"/>
    <child link="right_forearm_servo_1"/>
    <axis xyz="-0.054407 -0.004581 0.998508"/>
    <limit effort="100" lower="4.18879" upper="6.283185" velocity="100"/>
  </joint>
  <joint name="Rigid 14" type="fixed">
    <origin rpy="0 0 0" xyz="-0.00278 0.025503 -0.058247"/>
    <parent link="right_upper_arm_link_1"/>
    <child link="right_elbow_servo_1"/>
  </joint>
  <joint name="Rigid 16" type="fixed">
    <origin rpy="0 0 0" xyz="-0.029748 9.8e-05 -0.012039"/>
    <parent link="neck_connector_link_1"/>
    <child link="head_nod_servo_1"/>
  </joint>
  <joint name="Rigid 17" type="fixed">
    <origin rpy="0 0 0" xyz="-0.022157 0.037712 0.029792"/>
    <parent link="neck_connector_link_1"/>
    <child link="head_tilt_servo_1"/>
  </joint>
  <joint name="Rigid 18" type="fixed">
    <origin rpy="0 0 0" xyz="0.0215 -0.038225 -0.011028"/>
    <parent link="spine_connector_link_1"/>
    <child link="chest_tilt_servo_1"/>
  </joint>
  <joint name="Rigid 19" type="fixed">
    <origin rpy="0 0 0" xyz="0.03136 0.00017 -0.010399"/>
    <parent link="spine_connector_link_1"/>
    <child link="chest_bend_servo_1"/>
  </joint>
  <joint name="Rigid 20" type="fixed">
    <origin rpy="0 0 0" xyz="-0.011686 -0.144376 4e-06"/>
    <parent link="right_upper_leg_link_1"/>
    <child link="right_knee_Servo_1"/>
  </joint>
  <joint name="RightElbow" type="revolute">
    <origin rpy="0 0 0" xyz="-0.013179 0.001107 -0.03805"/>
    <parent link="right_elbow_servo_1"/>
    <child link="right_forearm_link_1"/>
    <axis xyz="-0.997045 0.008454 -0.07635"/>
    <limit effort="100" lower="-2.094395" upper="1.396263" velocity="100"/>
  </joint>
  <joint name="RightKnee" type="revolute">
    <origin rpy="0 0 0" xyz="-0.015238 -0.037289 0.0"/>
    <parent link="right_knee_Servo_1"/>
    <child link="right_lower_leg_link_1"/>
    <axis xyz="-0.999757 -0.022034 -0.0"/>
    <limit effort="100" lower="-0.872665" upper="1.570796" velocity="100"/>
  </joint>
  <joint name="Rigid 24" type="fixed">
    <origin rpy="0 0 0" xyz="0.013522 -0.000853 -0.1411"/>
    <parent link="right_lower_leg_link_1"/>
    <child link="right_ankle_servo_1"/>
  </joint>
  <joint name="RightAnkle" type="revolute">
    <origin rpy="0 0 0" xyz="-0.015233 -0.000335 -0.037289"/>
    <parent link="right_ankle_servo_1"/>
    <child link="right_foot_link_1"/>
    <axis xyz="0.999515 0.022029 0.022034"/>
    <limit effort="100" lower="0.0" upper="0.872665" velocity="100"/>
  </joint>
  <joint name="HeadTilt" type="revolute">
    <origin rpy="0 0 0" xyz="-0.021563 -0.012689 0.018935"/>
    <parent link="neck_connector_link_1"/>
    <child link="head_connector_link_1"/>
    <axis xyz="-0.000523 0.999956 0.009363"/>
    <limit effort="100" lower="-1.745329" upper="1.745329" velocity="100"/>
  </joint>
  <joint name="Rigid 28" type="fixed">
    <origin rpy="0 0 0" xyz="-0.003438 0.009009 0.062993"/>
    <parent link="head_connector_link_1"/>
    <child link="head_shell_1"/>
  </joint>
  <joint name="Rigid 29" type="fixed">
    <origin rpy="0 0 0" xyz="-0.001071 -0.007289 0.01961"/>
    <parent link="head_connector_link_1"/>
    <child link="eye_holder_1"/>
  </joint>
  <joint name="Rigid 30" type="fixed">
    <origin rpy="0 0 0" xyz="0.013958 -0.12348 -0.012417"/>
    <parent link="right_forearm_link_1"/>
    <child link="right_hand_link_1"/>
  </joint>
  <joint name="Rigid 31" type="fixed">
    <origin rpy="0 0 0" xyz="0.006774 -0.053173 -0.034835"/>
    <parent link="base_link"/>
    <child link="left_hip_servo_1"/>
  </joint>
  <joint name="LeftHip" type="revolute">
    <origin rpy="0 0 0" xyz="-0.027526 -0.058157 -3.5e-05"/>
    <parent link="base_link"/>
    <child link="left_upper_leg_link_1"/>
    <axis xyz="1.0 0.0 0.0"/>
    <limit effort="100" lower="4.18879" upper="6.283185" velocity="100"/>
  </joint>
  <joint name="Rigid 33" type="fixed">
    <origin rpy="0 0 0" xyz="0.011686 -0.147341 0.00452"/>
    <parent link="left_upper_leg_link_1"/>
    <child link="left_knee_servo_1"/>
  </joint>
  <joint name="LeftKnee" type="revolute">
    <origin rpy="0 0 0" xyz="0.015237 -0.035094 -0.005"/>
    <parent link="left_knee_servo_1"/>
    <child link="left_lower_leg_link_1"/>
    <axis xyz="0.999757 -0.022034 -0.0"/>
    <limit effort="100" lower="-1.570796" upper="0.872665" velocity="100"/>
  </joint>
  <joint name="Rigid 35" type="fixed">
    <origin rpy="0 0 0" xyz="-0.01362 -0.005302 -0.1434"/>
    <parent link="left_lower_leg_link_1"/>
    <child link="left_ankle_servo_1"/>
  </joint>
  <joint name="LeftAnkle" type="revolute">
    <origin rpy="0 0 0" xyz="0.015344 0.004663 -0.035094"/>
    <parent link="left_ankle_servo_1"/>
    <child link="left_foot_link_1"/>
    <axis xyz="-0.999515 0.022029 0.022034"/>
    <limit effort="100" lower="-0.872665" upper="0.0" velocity="100"/>
  </joint>
  <joint name="Rigid 37" type="fixed">
    <origin rpy="0 0 0" xyz="0.066173 -0.00196 0.048609"/>
    <parent link="chest_flat_back_link_1"/>
    <child link="left_chest_servo_1"/>
  </joint>
  <joint name="LeftChest" type="revolute">
    <origin rpy="0 0 0" xyz="0.018526 -0.015264 0.005769"/>
    <parent link="left_chest_servo_1"/>
    <child link="left_shoulder_connector_link_1"/>
    <axis xyz="-0.998272 0.022923 -0.054112"/>
    <limit effort="100" lower="-1.745329" upper="1.745329" velocity="100"/>
  </joint>
  <joint name="LeftShoulder" type="revolute">
    <origin rpy="0 0 0" xyz="0.027798 0.012641 0.001677"/>
    <parent link="left_shoulder_connector_link_1"/>
    <child link="left_shoulder_link_1"/>
    <axis xyz="-0.022021 -0.999609 -0.017211"/>
    <limit effort="100" lower="0.0" upper="4.18879" velocity="100"/>
  </joint>
  <joint name="Rigid 40" type="fixed">
    <origin rpy="0 0 0" xyz="0.003502 -0.031343 0.014753"/>
    <parent link="left_shoulder_link_1"/>
    <child link="left_shoulder_servo_1"/>
  </joint>
  <joint name="LeftBicep" type="revolute">
    <origin rpy="0 0 0" xyz="0.001628 -0.01359 -0.036271"/>
    <parent link="left_shoulder_link_1"/>
    <child link="left_forearm_servo_1"/>
    <axis xyz="0.054485 0.01599 -0.998387"/>
    <limit effort="100" lower="4.18879" upper="6.283185" velocity="100"/>
  </joint>
  <joint name="Rigid 42" type="fixed">
    <origin rpy="0 0 0" xyz="0.00527 -0.034545 -0.019453"/>
    <parent link="left_forearm_servo_1"/>
    <child link="left_upper_arm_link_1"/>
  </joint>
  <joint name="Rigid 43" type="fixed">
    <origin rpy="0 0 0" xyz="0.010086 0.031066 -0.059394"/>
    <parent link="left_upper_arm_link_1"/>
    <child link="left_elbow_servo_1"/>
  </joint>
  <joint name="LeftElbow" type="revolute">
    <origin rpy="0 0 0" xyz="0.017036 -0.004011 -0.034387"/>
    <parent link="left_elbow_servo_1"/>
    <child link="left_forearm_link_1"/>
    <axis xyz="-0.99924 0.02208 -0.032114"/>
    <limit effort="100" lower="-1.745329" upper="1.396263" velocity="100"/>
  </joint>
  <joint name="RightShoulder" type="revolute">
    <origin rpy="0 0 0" xyz="-0.027746 -0.03703 -0.002547"/>
    <parent link="right_shoulder_connector_link_1"/>
    <child link="right_shoulder_servo_1"/>
    <axis xyz="-0.006412 -0.999615 -0.027003"/>
    <limit effort="100" lower="3.141593" upper="6.283185" velocity="100"/>
  </joint>
  <joint name="Rigid 46" type="fixed">
    <origin rpy="0 0 0" xyz="-0.005675 0.018796 0.014967"/>
    <parent link="right_shoulder_servo_1"/>
    <child link="right_shoulder_link_1"/>
  </joint>
  <joint name="Rigid 47" type="fixed">
    <origin rpy="0 0 0" xyz="-0.004215 -0.034621 -0.019574"/>
    <parent link="right_forearm_servo_1"/>
    <child link="right_upper_arm_link_1"/>
  </joint>
  <joint name="Rigid 48" type="fixed">
    <origin rpy="0 0 0" xyz="-0.016241 -0.122852 -0.015485"/>
    <parent link="left_forearm_link_1"/>
    <child link="left_hand_link_1"/>
  </joint>
</robot>
